<?xml version="1.0"?>
<robot xmlns:xacro="http://www.ros.org/wiki/xacro" name="delivery_robot">

  <xacro:macro name="box_inertia" params="m w h d">
    <inertial>
      <origin xyz="0.05 0 0.02" rpy="0 0 0"/> 
      <mass value="${m}"/>
      <inertia ixx="${(m/12) * (h*h + d*d)}" ixy="0.0" ixz="0.0" iyy="${(m/12) * (w*w + d*d)}" iyz="0.0" izz="${(m/12) * (w*w + h*h)}"/>
    </inertial>
  </xacro:macro>

  <xacro:macro name="cylinder_inertia" params="m r h">
    <inertial>
      <mass value="${m}"/>
      <inertia ixx="${(m/12) * (3*r*r + h*h)}" ixy="0" ixz="0" iyy="${(m/12) * (3*r*r + h*h)}" iyz="0" izz="${(m/2) * (r*r)}"/>
    </inertial>
  </xacro:macro>

  <link name="base_footprint"/>

  <joint name="base_footprint_joint" type="fixed">
  <parent link="base_footprint"/>
  <child link="base_link"/>
  <origin xyz="0 0 0.0325" rpy="0 0 0"/> </joint>
  
  <link name="base_link">
    <visual>
      <geometry><box size="0.297 0.210 0.005"/></geometry>
      <material name="dark_grey"><color rgba="0.2 0.2 0.2 1"/></material>
    </visual>
    <collision>
      <geometry><box size="0.297 0.210 0.005"/></geometry>
    </collision>
    <xacro:box_inertia m="2.0" w="0.210" h="0.005" d="0.297"/>
  </link>

  <xacro:macro name="wheel" params="prefix x_reflect y_reflect">
    <link name="${prefix}_wheel">
      <visual>
        <origin xyz="0 0 0" rpy="${pi/2} 0 0"/>
        <geometry><cylinder radius="0.0325" length="0.025"/></geometry>
        <material name="black"><color rgba="0 0 0 1"/></material>
      </visual>
      <collision>
        <origin xyz="0 0 0" rpy="${pi/2} 0 0"/>
        <geometry><cylinder radius="0.0325" length="0.025"/></geometry>
      </collision>
      <xacro:cylinder_inertia m="0.1" r="0.0325" h="0.025"/>
    </link>
    <joint name="${prefix}_wheel_joint" type="continuous">
      <parent link="base_link"/><child link="${prefix}_wheel"/>
      <origin xyz="${x_reflect*0.1} ${y_reflect*0.12} -0.02" rpy="0 0 0"/>
      <axis xyz="0 1 0"/>
    </joint>
  </xacro:macro>

  <xacro:wheel prefix="front_left"  x_reflect="1"  y_reflect="1" />
  <xacro:wheel prefix="front_right" x_reflect="1"  y_reflect="-1" />
  <xacro:wheel prefix="rear_left"   x_reflect="-1" y_reflect="1" />
  <xacro:wheel prefix="rear_right"  x_reflect="-1" y_reflect="-1" />

  <link name="top_plate">
    <visual>
      <geometry><box size="0.297 0.210 0.005"/></geometry>
      <material name="white"><color rgba="1 1 1 1"/></material>
    </visual>
    <collision><geometry><box size="0.297 0.210 0.005"/></geometry></collision>
    <xacro:box_inertia m="0.4" w="0.210" h="0.005" d="0.297"/>
  </link>
  <joint name="top_plate_joint" type="fixed">
    <parent link="base_link"/><child link="top_plate"/>
    <origin xyz="0 0 0.1"/>
  </joint>

  <link name="tray_stand">
    <visual>
      <geometry><cylinder radius="0.01" length="0.05"/></geometry>
      <material name="grey"><color rgba="0.5 0.5 0.5 1"/></material>
    </visual>
    <xacro:cylinder_inertia m="0.1" r="0.01" h="0.05"/>
  </link>
  <joint name="tray_stand_joint" type="fixed">
    <parent link="top_plate"/><child link="tray_stand"/>
    <origin xyz="0 0 0.025"/>
  </joint>

  <link name="tray_link">
    <visual>
      <geometry><box size="0.25 0.20 0.005"/></geometry>
      <material name="grey"><color rgba="0.5 0.5 0.5 1"/></material>
    </visual>
    <xacro:box_inertia m="0.2" w="0.20" h="0.005" d="0.25"/>
  </link>
  <joint name="tray_joint" type="fixed">
    <parent link="tray_stand"/><child link="tray_link"/>
    <origin xyz="0 0 0.025"/>
  </joint>

  <link name="payload_link">
    <visual>
      <origin xyz="0 0 0.05"/>
      <geometry><box size="0.15 0.15 0.1"/></geometry>
      <material name="blue"><color rgba="0 0 0.8 1"/></material>
    </visual>
    <xacro:box_inertia m="1.5" w="0.15" h="0.1" d="0.15"/>
  </link>
  <joint name="payload_joint" type="fixed">
    <parent link="tray_link"/><child link="payload_link"/>
    <origin xyz="0 0 0.005"/>
  </joint>

  <link name="lidar_link">
    <visual>
      <geometry><cylinder radius="0.035" length="0.04"/></geometry>
      <material name="black"><color rgba="0 0 0 1"/></material> </visual>
    <collision>
      <geometry><cylinder radius="0.035" length="0.04"/></geometry>
    </collision>
    <xacro:cylinder_inertia m="0.15" r="0.035" h="0.04"/>
  </link>
  <joint name="lidar_joint" type="fixed">
    <parent link="top_plate"/><child link="lidar_link"/>
    <origin xyz="0.13 0 0.02" rpy="0 0 0"/> 
  </joint>

  <gazebo reference="base_link"><material>Gazebo/Grey</material></gazebo>
  <gazebo reference="top_plate"><material>Gazebo/White</material></gazebo>
  <gazebo reference="payload_link"><material>Gazebo/Blue</material></gazebo>
  
  <gazebo>
    <plugin name="skid_steer" filename="libgazebo_ros_diff_drive.so">
      <num_wheel_pairs>2</num_wheel_pairs>
      
      <left_joint>front_left_wheel_joint</left_joint>
      <left_joint>rear_left_wheel_joint</left_joint>
      <right_joint>front_right_wheel_joint</right_joint>
      <right_joint>rear_right_wheel_joint</right_joint>
      
      <wheel_separation>0.245</wheel_separation>
      <wheel_diameter>0.065</wheel_diameter>
      <max_wheel_torque>5.0</max_wheel_torque>
      <max_wheel_acceleration>1.0</max_wheel_acceleration>

      <publish_odom>true</publish_odom>
      <publish_odom_tf>true</publish_odom_tf> <publish_wheel_tf>true</publish_wheel_tf>
      
      <odometry_frame>odom</odometry_frame>
      <robot_base_frame>base_footprint</robot_base_frame>
      
      <command_topic>cmd_vel</command_topic>
      <odometry_topic>odom</odometry_topic>
    </plugin>
  </gazebo>

  <gazebo reference="lidar_link">
    <sensor name="lidar" type="ray">
      <visualize>true</visualize>
      <update_rate>10</update_rate>
      <ray>
        <scan><horizontal><samples>360</samples><min_angle>-3.14</min_angle><max_angle>3.14</max_angle></horizontal></scan>
        <range>
        <min>0.20</min>
        <max>10.0</max>
        <resolution>0.01</resolution>
        </range>
      </ray>
      <plugin name="gazebo_ros_lidar" filename="libgazebo_ros_ray_sensor.so">
        <ros><remapping>~/out:=scan</remapping></ros>
        <output_type>sensor_msgs/LaserScan</output_type>
        <frame_name>lidar_link</frame_name>
      </plugin>
    </sensor>
  </gazebo>
  <gazebo reference="front_left_wheel">
    <mu1>0.1</mu1>
    <mu2>0.1</mu2>
    <kp>1000000.0</kp>
    <kd>10.0</kd>
  </gazebo>

  <gazebo reference="front_right_wheel">
    <mu1>0.1</mu1>
    <mu2>0.1</mu2>
    <kp>1000000.0</kp>
    <kd>10.0</kd>
  </gazebo>

  <gazebo reference="rear_left_wheel">
    <mu1>0.1</mu1>
    <mu2>0.1</mu2>
    <kp>1000000.0</kp>
    <kd>10.0</kd>
  </gazebo>

  <gazebo reference="rear_right_wheel">
    <mu1>0.1</mu1>
    <mu2>0.1</mu2>
    <kp>1000000.0</kp>
    <kd>10.0</kd>
  </gazebo>

</robot>